<?xml version="1.0"?>
<robot name="jetbot">
  <!-- Chassis -->
  <link name="chassis">
    <visual>
      <origin xyz="0 0 0.043" rpy="1.5708 0 1.5708"/>
      <geometry>
        <mesh filename="package://dev_ws/config/JetBot-v3-Chassis_simplified.stl" scale="0.001 0.001 0.001"/>
      </geometry>
    </visual>
    <collision>
      <origin xyz="0 0 0.043" rpy="1.5708 0 1.5708"/>
      <geometry>
        <mesh filename="package://dev_ws/config/JetBot-v3-Chassis.dae" scale="0.001 0.001 0.001"/>
      </geometry>
    </collision>
    <inertial>
      <origin xyz="0 -0.01 -0.02" rpy="0 0 0"/>
      <mass value="1.0"/>
      <inertia ixx="0.001" ixy="0.0" ixz="0.0" iyy="0.001" iyz="0.0" izz="0.001"/>
    </inertial>
  </link>

  <!-- Left Wheel -->
  <link name="left_wheel">
    <visual>
      <origin xyz="0.03 0.05125 0.03" rpy="0 0 1.5708"/>
      <geometry>
        <mesh filename="package://dev_ws/config/JetBot-v3-Wheel.stl" scale="0.001 0.001 0.001"/>
      </geometry>
    </visual>
    <collision>
      <origin xyz="0.03 0.05125 0.03" rpy="0 0 1.5708"/>
      <geometry>
        <mesh filename="package://dev_ws/config/JetBot-v3-Wheel.stl" scale="0.001 0.001 0.001"/>
      </geometry>
    </collision>
    <inertial>
      <mass value="0.2"/>
      <inertia ixx="0.0001" ixy="0.0" ixz="0.0" iyy="0.0001" iyz="0.0" izz="0.0001"/>
    </inertial>
  </link>

  <!-- Right Wheel -->
  <link name="right_wheel">
    <visual>
      <origin xyz="0.03 -0.0595 0.03" rpy="0 0 1.5708"/>
      <geometry>
        <mesh filename="package://dev_ws/config/JetBot-v3-Wheel.stl" scale="0.001 0.001 0.001"/>
      </geometry>
    </visual>
    <collision>
      <origin xyz="0.03 -0.0595 0.03" rpy="0 0 1.5708"/>
      <geometry>
        <mesh filename="package://dev_ws/config/JetBot-v3-Wheel.stl" scale="0.001 0.001 0.001"/>
      </geometry>
    </collision>
    <inertial>
      <mass value="0.2"/>
      <inertia ixx="0.0001" ixy="0.0" ixz="0.0" iyy="0.0001" iyz="0.0" izz="0.0001"/>
    </inertial>
  </link>

  <!-- Left Wheel Joint -->
  <joint name="left_wheel_joint" type="revolute">
    <parent link="chassis"/>
    <child link="left_wheel"/>
    <origin xyz="0.03 0.05125 0.03" rpy="0 0 0"/>
    <axis xyz="0 1 0"/>
    <limit effort="0.5" velocity="5.0" lower="-3.14" upper="3.14"/>
  </joint>

  <!-- Right Wheel Joint -->
  <joint name="right_wheel_joint" type="revolute">
    <parent link="chassis"/>
    <child link="right_wheel"/>
    <origin xyz="0.03 -0.0595 0.03" rpy="0 0 0"/>
    <axis xyz="0 1 0"/>
    <limit effort="0.5" velocity="5.0" lower="-3.14" upper="3.14"/>
  </joint>

  <!-- Camera (optional, for future use) -->
  <!--
  <link name="camera_link">
    <visual>
      <origin xyz="0.055 0.0 0.0857" rpy="0 0.25 0"/>
      <geometry>
        <box size="0.01 0.01 0.01"/>
      </geometry>
    </visual>
    <inertial>
      <mass value="0.01"/>
      <inertia ixx="0.00001" ixy="0.0" ixz="0.0" iyy="0.00001" iyz="0.0" izz="0.00001"/>
    </inertial>
  </link>

  <joint name="camera_joint" type="fixed">
    <parent link="chassis"/>
    <child link="camera_link"/>
    <origin xyz="0.055 0.0 0.0857" rpy="0 0.25 0"/>
  </joint>
  -->

</robot>
